[2025-05-14T00:12:14.787+0000] {taskinstance.py:1956} INFO - Dependencies all met for dep_context=non-requeueable deps ti=<TaskInstance: earthquake_etl_pipeline.download_data manual__2025-05-14T00:12:02.815284+00:00 [queued]>
[2025-05-14T00:12:14.800+0000] {taskinstance.py:1956} INFO - Dependencies all met for dep_context=requeueable deps ti=<TaskInstance: earthquake_etl_pipeline.download_data manual__2025-05-14T00:12:02.815284+00:00 [queued]>
[2025-05-14T00:12:14.801+0000] {taskinstance.py:2170} INFO - Starting attempt 1 of 2
[2025-05-14T00:12:14.819+0000] {taskinstance.py:2191} INFO - Executing <Task(BashOperator): download_data> on 2025-05-14 00:12:02.815284+00:00
[2025-05-14T00:12:14.829+0000] {standard_task_runner.py:60} INFO - Started process 117 to run task
[2025-05-14T00:12:14.832+0000] {standard_task_runner.py:87} INFO - Running: ['***', 'tasks', 'run', 'earthquake_etl_pipeline', 'download_data', 'manual__2025-05-14T00:12:02.815284+00:00', '--job-id', '3', '--raw', '--subdir', 'DAGS_FOLDER/etl_pipeline.py', '--cfg-path', '/tmp/tmpcssg2z1p']
[2025-05-14T00:12:14.835+0000] {standard_task_runner.py:88} INFO - Job 3: Subtask download_data
[2025-05-14T00:12:14.896+0000] {task_command.py:423} INFO - Running <TaskInstance: earthquake_etl_pipeline.download_data manual__2025-05-14T00:12:02.815284+00:00 [running]> on host ac010fa9152e
[2025-05-14T00:12:14.946+0000] {abstractoperator.py:707} ERROR - Exception rendering Jinja template for task 'download_data', field 'bash_command'. Template: 'bash /opt/***/scripts/download_data.sh'
Traceback (most recent call last):
  File "/home/airflow/.local/lib/python3.8/site-packages/airflow/models/abstractoperator.py", line 699, in _do_render_template_fields
    rendered_content = self.render_template(
  File "/home/airflow/.local/lib/python3.8/site-packages/airflow/template/templater.py", line 171, in render_template
    template = jinja_env.get_template(value)
  File "/home/airflow/.local/lib/python3.8/site-packages/jinja2/environment.py", line 1010, in get_template
    return self._load_template(name, globals)
  File "/home/airflow/.local/lib/python3.8/site-packages/jinja2/environment.py", line 969, in _load_template
    template = self.loader.load(self, name, self.make_globals(globals))
  File "/home/airflow/.local/lib/python3.8/site-packages/jinja2/loaders.py", line 125, in load
    source, filename, uptodate = self.get_source(environment, name)
  File "/home/airflow/.local/lib/python3.8/site-packages/jinja2/loaders.py", line 204, in get_source
    raise TemplateNotFound(template)
jinja2.exceptions.TemplateNotFound: bash /opt/airflow/scripts/download_data.sh
[2025-05-14T00:12:14.949+0000] {taskinstance.py:2698} ERROR - Task failed with exception
Traceback (most recent call last):
  File "/home/airflow/.local/lib/python3.8/site-packages/airflow/models/taskinstance.py", line 2334, in _run_raw_task
    self._execute_task_with_callbacks(context, test_mode, session=session)
  File "/home/airflow/.local/lib/python3.8/site-packages/airflow/models/taskinstance.py", line 2465, in _execute_task_with_callbacks
    task_orig = self.render_templates(context=context)
  File "/home/airflow/.local/lib/python3.8/site-packages/airflow/models/taskinstance.py", line 2877, in render_templates
    original_task.render_template_fields(context)
  File "/home/airflow/.local/lib/python3.8/site-packages/airflow/models/baseoperator.py", line 1241, in render_template_fields
    self._do_render_template_fields(self, self.template_fields, context, jinja_env, set())
  File "/home/airflow/.local/lib/python3.8/site-packages/airflow/utils/session.py", line 79, in wrapper
    return func(*args, session=session, **kwargs)
  File "/home/airflow/.local/lib/python3.8/site-packages/airflow/models/abstractoperator.py", line 699, in _do_render_template_fields
    rendered_content = self.render_template(
  File "/home/airflow/.local/lib/python3.8/site-packages/airflow/template/templater.py", line 171, in render_template
    template = jinja_env.get_template(value)
  File "/home/airflow/.local/lib/python3.8/site-packages/jinja2/environment.py", line 1010, in get_template
    return self._load_template(name, globals)
  File "/home/airflow/.local/lib/python3.8/site-packages/jinja2/environment.py", line 969, in _load_template
    template = self.loader.load(self, name, self.make_globals(globals))
  File "/home/airflow/.local/lib/python3.8/site-packages/jinja2/loaders.py", line 125, in load
    source, filename, uptodate = self.get_source(environment, name)
  File "/home/airflow/.local/lib/python3.8/site-packages/jinja2/loaders.py", line 204, in get_source
    raise TemplateNotFound(template)
jinja2.exceptions.TemplateNotFound: bash /opt/airflow/scripts/download_data.sh
[2025-05-14T00:12:14.959+0000] {taskinstance.py:1138} INFO - Marking task as UP_FOR_RETRY. dag_id=earthquake_etl_pipeline, task_id=download_data, execution_date=20250514T001202, start_date=20250514T001214, end_date=20250514T001214
[2025-05-14T00:12:14.976+0000] {standard_task_runner.py:107} ERROR - Failed to execute job 3 for task download_data (bash /opt/airflow/scripts/download_data.sh; 117)
[2025-05-14T00:12:15.006+0000] {local_task_job_runner.py:234} INFO - Task exited with return code 1
[2025-05-14T00:12:15.031+0000] {taskinstance.py:3280} INFO - 0 downstream tasks scheduled from follow-on schedule check
